Workbook
Name CT: '[1]Bảng tra'!$A$18:$C$33
Name CT: 'Bảng tra'!$A$18:$C$33
Name THEP: '[2]Bảng tra'!$A$2:$C$17

Sheet Tra
B3: Soá lieäu tính toaùn
C4: Beâtoâng Maùc | G4: M250 | L4: L2/L1 | M4: m1 | N4: m2 | O4: k1 | P4: k2 | Q4: Δm1 | R4: Δm2 | S4: Δk1 | T4: Δk2 | U4: L2/L1 | V4: m1 | W4: m2 | X4: k1 | Y4: k2
D5: Rn= | G5: =IF(G4="M200",90,IF(G4="M250",110,IF(G4="M300",130,"Maùc beâ toâng"))) -> 110 | J5: Kg/cm² | L5: 1 | M5: 0.0099 | N5: 0.0457 | O5: 0.051 | P5: 0.0853 | Q5: =+(M6-M5)/(L6-L5) -> 0.003 | R5: =+(N6-N5)/(L6-L5) -> 0.035 | S5: =+(O6-O5)/(L6-L5) -> 0.064 | T5: =+(P6-P5)/(L6-L5) -> 0.077 | U5: 1 | V5: =+IF($U5<=1.5,IF($U5<=1.4,IF($U5<=1.3,IF($U5<=1.2,IF($U5<=1.1,M$5+($U5-$L$5)*Q$5,M$6+($U5-$L$6)*Q$6),M$7+($U5-$L$7)*Q$7),M$8+($U5-$L$8)*Q$8),M$9+($U5-$L$9)*Q$9),M$10) -> 0.0099 | W5: =+IF($U5<=1.5,IF($U5<=1.4,IF($U5<=1.3,IF($U5<=1.2,IF($U5<=1.1,N$5+($U5-$L$5)*R$5,N$6+($U5-$L$6)*R$6),N$7+($U5-$L$7)*R$7),N$8+($U5-$L$8)*R$8),N$9+($U5-$L$9)*R$9),N$10) -> 0.0457 | X5: =+IF($U5<=1.5,IF($U5<=1.4,IF($U5<=1.3,IF($U5<=1.2,IF($U5<=1.1,O$5+($U5-$L$5)*S$5,O$6+($U5-$L$6)*S$6),O$7+($U5-$L$7)*S$7),O$8+($U5-$L$8)*S$8),O$9+($U5-$L$9)*S$9),O$10) -> 0.051 | Y5: =+IF($U5<=1.5,IF($U5<=1.4,IF($U5<=1.3,IF($U5<=1.2,IF($U5<=1.1,P$5+($U5-$L$5)*T$5,P$6+($U5-$L$6)*T$6),P$7+($U5-$L$7)*T$7),P$8+($U5-$L$8)*T$8),P$9+($U5-$L$9)*T$9),P$10) -> 0.0853
D6: Rk= | G6: =IF(G4="M200",7.5,IF(G4="M250",8.8,IF(G4="M300",10,"Maùc be toâng"))) -> 8.8 | L6: 1.1 | M6: 0.0102 | N6: 0.0492 | O6: 0.0574 | P6: 0.093 | Q6: =+(M7-M6)/(L7-L6) -> 0 | R6: =+(N7-N6)/(L7-L6) -> 0.027 | S6: =+(O7-O6)/(L7-L6) -> 0.062 | T6: =+(P7-P6)/(L7-L6) -> 0.07 | U6: 1.1 | V6: =+IF($U6<=1.5,IF($U6<=1.4,IF($U6<=1.3,IF($U6<=1.2,IF($U6<=1.1,M$5+($U6-$L$5)*Q$5,M$6+($U6-$L$6)*Q$6),M$7+($U6-$L$7)*Q$7),M$8+($U6-$L$8)*Q$8),M$9+($U6-$L$9)*Q$9),M$10) -> 0.0102 | W6: =+IF($U6<=1.5,IF($U6<=1.4,IF($U6<=1.3,IF($U6<=1.2,IF($U6<=1.1,N$5+($U6-$L$5)*R$5,N$6+($U6-$L$6)*R$6),N$7+($U6-$L$7)*R$7),N$8+($U6-$L$8)*R$8),N$9+($U6-$L$9)*R$9),N$10) -> 0.0492 | X6: =+IF($U6<=1.5,IF($U6<=1.4,IF($U6<=1.3,IF($U6<=1.2,IF($U6<=1.1,O$5+($U6-$L$5)*S$5,O$6+($U6-$L$6)*S$6),O$7+($U6-$L$7)*S$7),O$8+($U6-$L$8)*S$8),O$9+($U6-$L$9)*S$9),O$10) -> 0.0574 | Y6: =+IF($U6<=1.5,IF($U6<=1.4,IF($U6<=1.3,IF($U6<=1.2,IF($U6<=1.1,P$5+($U6-$L$5)*T$5,P$6+($U6-$L$6)*T$6),P$7+($U6-$L$7)*T$7),P$8+($U6-$L$8)*T$8),P$9+($U6-$L$9)*T$9),P$10) -> 0.093
C7: Nhoùm coát theùp baûn | G7: AII | L7: 1.2 | M7: 0.0102 | N7: 0.0519 | O7: 0.0636 | P7: 0.1 | Q7: =+(M8-M7)/(L8-L7) -> 0.908 | R7: =+(N8-N7)/(L8-L7) -> 0.021 | S7: =+(O8-O7)/(L8-L7) -> 0.064 | T7: =+(P8-P7)/(L8-L7) -> 0.062 | U7: 1.2 | V7: =+IF($U7<=1.5,IF($U7<=1.4,IF($U7<=1.3,IF($U7<=1.2,IF($U7<=1.1,M$5+($U7-$L$5)*Q$5,M$6+($U7-$L$6)*Q$6),M$7+($U7-$L$7)*Q$7),M$8+($U7-$L$8)*Q$8),M$9+($U7-$L$9)*Q$9),M$10) -> 0.0102 | W7: =+IF($U7<=1.5,IF($U7<=1.4,IF($U7<=1.3,IF($U7<=1.2,IF($U7<=1.1,N$5+($U7-$L$5)*R$5,N$6+($U7-$L$6)*R$6),N$7+($U7-$L$7)*R$7),N$8+($U7-$L$8)*R$8),N$9+($U7-$L$9)*R$9),N$10) -> 0.0519 | X7: =+IF($U7<=1.5,IF($U7<=1.4,IF($U7<=1.3,IF($U7<=1.2,IF($U7<=1.1,O$5+($U7-$L$5)*S$5,O$6+($U7-$L$6)*S$6),O$7+($U7-$L$7)*S$7),O$8+($U7-$L$8)*S$8),O$9+($U7-$L$9)*S$9),O$10) -> 0.0636 | Y7: =+IF($U7<=1.5,IF($U7<=1.4,IF($U7<=1.3,IF($U7<=1.2,IF($U7<=1.1,P$5+($U7-$L$5)*T$5,P$6+($U7-$L$6)*T$6),P$7+($U7-$L$7)*T$7),P$8+($U7-$L$8)*T$8),P$9+($U7-$L$9)*T$9),P$10) -> 0.1
D8: Ra= | G8: =IF(G7="AI",2200,IF(G7="AII",2800,IF(G7="AIII",3600,"Nhoùm coát theùp"))) -> 2800 | J8: Kg/cm² | L8: 1.3 | M8: 0.101 | N8: 0.054 | O8: 0.07 | P8: 0.1062 | Q8: =+(M9-M8)/(L9-L8) -> -0.913 | R8: =+(N9-N8)/(L9-L8) -> 0.012 | S8: =+(O9-O8)/(L9-L8) -> 0.061 | T8: =+(P9-P8)/(L9-L8) -> 0.053 | U8: 1.3 | V8: =+IF($U8<=1.5,IF($U8<=1.4,IF($U8<=1.3,IF($U8<=1.2,IF($U8<=1.1,M$5+($U8-$L$5)*Q$5,M$6+($U8-$L$6)*Q$6),M$7+($U8-$L$7)*Q$7),M$8+($U8-$L$8)*Q$8),M$9+($U8-$L$9)*Q$9),M$10) -> 0.101 | W8: =+IF($U8<=1.5,IF($U8<=1.4,IF($U8<=1.3,IF($U8<=1.2,IF($U8<=1.1,N$5+($U8-$L$5)*R$5,N$6+($U8-$L$6)*R$6),N$7+($U8-$L$7)*R$7),N$8+($U8-$L$8)*R$8),N$9+($U8-$L$9)*R$9),N$10) -> 0.054 | X8: =+IF($U8<=1.5,IF($U8<=1.4,IF($U8<=1.3,IF($U8<=1.2,IF($U8<=1.1,O$5+($U8-$L$5)*S$5,O$6+($U8-$L$6)*S$6),O$7+($U8-$L$7)*S$7),O$8+($U8-$L$8)*S$8),O$9+($U8-$L$9)*S$9),O$10) -> 0.07 | Y8: =+IF($U8<=1.5,IF($U8<=1.4,IF($U8<=1.3,IF($U8<=1.2,IF($U8<=1.1,P$5+($U8-$L$5)*T$5,P$6+($U8-$L$6)*T$6),P$7+($U8-$L$7)*T$7),P$8+($U8-$L$8)*T$8),P$9+($U8-$L$9)*T$9),P$10) -> 0.1062
D9: BTBV | G9: 5 | J9: cm | L9: 1.4 | M9: 0.0097 | N9: 0.0552 | O9: 0.0761 | P9: 0.1115 | Q9: =+(M10-M9)/(L10-L9) -> -0.002 | R9: =+(N10-N9)/(L10-L9) -> 0.004 | S9: =+(O10-O9)/(L10-L9) -> 0.06 | T9: =+(P10-P9)/(L10-L9) -> 0.04 | U9: =+#REF! -> #REF! | V9: =+IF($U9<=1.5,IF($U9<=1.4,IF($U9<=1.3,IF($U9<=1.2,IF($U9<=1.1,M$5+($U9-$L$5)*Q$5,M$6+($U9-$L$6)*Q$6),M$7+($U9-$L$7)*Q$7),M$8+($U9-$L$8)*Q$8),M$9+($U9-$L$9)*Q$9),M$10) -> #REF! | W9: =+IF($U9<=1.5,IF($U9<=1.4,IF($U9<=1.3,IF($U9<=1.2,IF($U9<=1.1,N$5+($U9-$L$5)*R$5,N$6+($U9-$L$6)*R$6),N$7+($U9-$L$7)*R$7),N$8+($U9-$L$8)*R$8),N$9+($U9-$L$9)*R$9),N$10) -> #REF! | X9: =+IF($U9<=1.5,IF($U9<=1.4,IF($U9<=1.3,IF($U9<=1.2,IF($U9<=1.1,O$5+($U9-$L$5)*S$5,O$6+($U9-$L$6)*S$6),O$7+($U9-$L$7)*S$7),O$8+($U9-$L$8)*S$8),O$9+($U9-$L$9)*S$9),O$10) -> #REF! | Y9: =+IF($U9<=1.5,IF($U9<=1.4,IF($U9<=1.3,IF($U9<=1.2,IF($U9<=1.1,P$5+($U9-$L$5)*T$5,P$6+($U9-$L$6)*T$6),P$7+($U9-$L$7)*T$7),P$8+($U9-$L$8)*T$8),P$9+($U9-$L$9)*T$9),P$10) -> #REF!
D10: Þ | G10: 12 | L10: 1.5 | M10: 0.0095 | N10: 0.0556 | O10: 0.0821 | P10: 0.1155 | U10: 1.091 | V10: =+IF($U10<=1.5,IF($U10<=1.4,IF($U10<=1.3,IF($U10<=1.2,IF($U10<=1.1,M$5+($U10-$L$5)*Q$5,M$6+($U10-$L$6)*Q$6),M$7+($U10-$L$7)*Q$7),M$8+($U10-$L$8)*Q$8),M$9+($U10-$L$9)*Q$9),M$10) -> 0.010173 | W10: =+IF($U10<=1.5,IF($U10<=1.4,IF($U10<=1.3,IF($U10<=1.2,IF($U10<=1.1,N$5+($U10-$L$5)*R$5,N$6+($U10-$L$6)*R$6),N$7+($U10-$L$7)*R$7),N$8+($U10-$L$8)*R$8),N$9+($U10-$L$9)*R$9),N$10) -> 0.048885 | X10: =+IF($U10<=1.5,IF($U10<=1.4,IF($U10<=1.3,IF($U10<=1.2,IF($U10<=1.1,O$5+($U10-$L$5)*S$5,O$6+($U10-$L$6)*S$6),O$7+($U10-$L$7)*S$7),O$8+($U10-$L$8)*S$8),O$9+($U10-$L$9)*S$9),O$10) -> 0.056824 | Y10: =+IF($U10<=1.5,IF($U10<=1.4,IF($U10<=1.3,IF($U10<=1.2,IF($U10<=1.1,P$5+($U10-$L$5)*T$5,P$6+($U10-$L$6)*T$6),P$7+($U10-$L$7)*T$7),P$8+($U10-$L$8)*T$8),P$9+($U10-$L$9)*T$9),P$10) -> 0.092307
C11: Nhoùm coát theùp daàm | G11: AIII
D12: Ra= | G12: =IF(G11="AI",2200,IF(G11="AII",2800,IF(G11="AIII",3600,"Nhoùm coát theùp"))) -> 3600 | J12: Kg/cm²
D13: BTBV | G13: 5 | J13: cm
C15: Giaù trò heä soá k
D16: n=l/b : | G16: Tæ soá 2 caïnh
C17: (1) | D17: (2) | E17: (3) | F17: (4) | G17: (5) | H17: (6) | I17: (7) | J17: (8)
C18: 2z/b | D18: 1 | E18: 1.1 | F18: =+G18/2+E18/2 -> 1.15 | G18: 1.2 | H18: =+G18/2+I18/2 -> 1.25 | I18: =+G18/2+J18/2 -> 1.3 | J18: 1.4
C19: 0 | D19: 1 | E19: =+(D19+G19)/2 -> 1 | F19: =+E19/2+G19/2 -> 1 | G19: 1 | H19: =+G19/2+I19/2 -> 1 | I19: =+G19/2+J19/2 -> 1 | J19: 1
C20: =+C19/2+C21/2 -> 0.05 | D20: =+D19/2+D21/2 -> 0.995 | E20: =+(D20+G20)/2 -> 0.9955 | F20: =+E20/2+G20/2 -> 0.99575 | G20: =+G19/2+G21/2 -> 0.996 | H20: =+G20/2+I20/2 -> 0.996125 | I20: =+G20/2+J20/2 -> 0.99625 | J20: =+J19/2+J21/2 -> 0.9965
C21: 0.1 | D21: =+(D19+D23)/2 -> 0.99 | E21: =+(D21+G21)/2 -> 0.991 | F21: =+E21/2+G21/2 -> 0.9915 | G21: =+(G19+G23)/2 -> 0.992 | H21: =+G21/2+I21/2 -> 0.99225 | I21: =+G21/2+J21/2 -> 0.9925 | J21: =+(J19+J23)/2 -> 0.993
C22: 0.15 | D22: =+D21/2+D23/2 -> 0.985 | E22: =+(D22+G22)/2 -> 0.9865 | F22: =+E22/2+G22/2 -> 0.98725 | G22: =+G21/2+G23/2 -> 0.988 | H22: =+G22/2+I22/2 -> 0.988375 | I22: =+G22/2+J22/2 -> 0.98875 | J22: =+J21/2+J23/2 -> 0.9895
C23: 0.2 | D23: =+D27/2+D19/2 -> 0.98 | E23: =+(D23+G23)/2 -> 0.982 | F23: =+E23/2+G23/2 -> 0.983 | G23: =+G27/2+G19/2 -> 0.984 | H23: =+G23/2+I23/2 -> 0.9845 | I23: =+G23/2+J23/2 -> 0.985 | J23: =+J27/2+J19/2 -> 0.986
C24: =+C23/2+C25/2 -> 0.25 | D24: =+D23/2+D25/2 -> 0.975 | E24: =+(D24+G24)/2 -> 0.9775 | F24: =+E24/2+G24/2 -> 0.97875 | G24: =+G23/2+G25/2 -> 0.98 | H24: =+G24/2+I24/2 -> 0.980625 | I24: =+G24/2+J24/2 -> 0.98125 | J24: =+J23/2+J25/2 -> 0.9825
C25: 0.3 | D25: =+(D23+D27)/2 -> 0.97 | E25: =+(D25+G25)/2 -> 0.973 | F25: =+E25/2+G25/2 -> 0.9745 | G25: =+(G23+G27)/2 -> 0.976 | H25: =+G25/2+I25/2 -> 0.97675 | I25: =+G25/2+J25/2 -> 0.9775 | J25: =+(J23+J27)/2 -> 0.979
C26: =+C25/2+C27/2 -> 0.35 | D26: =+D25/2+D27/2 -> 0.965 | E26: =+(D26+G26)/2 -> 0.9685 | F26: =+E26/2+G26/2 -> 0.97025 | G26: =+G25/2+G27/2 -> 0.972 | H26: =+G26/2+I26/2 -> 0.972875 | I26: =+G26/2+J26/2 -> 0.97375 | J26: =+J25/2+J27/2 -> 0.9755
C27: 0.4 | D27: 0.96 | E27: =+(D27+G27)/2 -> 0.964 | F27: =+E27/2+G27/2 -> 0.966 | G27: 0.968 | H27: =+G27/2+I27/2 -> 0.969 | I27: =+G27/2+J27/2 -> 0.97 | J27: 0.972
C28: =+C27/2+C29/2 -> 0.45 | D28: =+D27/2+D29/2 -> 0.94 | E28: =+(D28+G28)/2 -> 0.945375 | F28: =+E28/2+G28/2 -> 0.9480625 | G28: =+G27/2+G29/2 -> 0.95075 | H28: =+G28/2+I28/2 -> 0.9521875 | I28: =+G28/2+J28/2 -> 0.953625 | J28: =+J27/2+J29/2 -> 0.9565
C29: 0.5 | D29: =+D27/2+D31/2 -> 0.92 | E29: =+(D29+G29)/2 -> 0.92675 | F29: =+E29/2+G29/2 -> 0.930125 | G29: =+G27/2+G31/2 -> 0.9335 | H29: =+G29/2+I29/2 -> 0.935375 | I29: =+G29/2+J29/2 -> 0.93725 | J29: =+J27/2+J31/2 -> 0.941
C30: =+C29/2+C31/2 -> 0.55 | D30: =+D29/2+D31/2 -> 0.9 | E30: =+(D30+G30)/2 -> 0.908125 | F30: =+E30/2+G30/2 -> 0.9121875 | G30: =+G29/2+G31/2 -> 0.91625 | H30: =+G30/2+I30/2 -> 0.9185625 | I30: =+G30/2+J30/2 -> 0.920875 | J30: =+J29/2+J31/2 -> 0.9255
C31: 0.6 | D31: =+D27/2+D35/2 -> 0.88 | E31: =+(D31+G31)/2 -> 0.8895 | F31: =+E31/2+G31/2 -> 0.89425 | G31: =+G27/2+G35/2 -> 0.899 | H31: =+G31/2+I31/2 -> 0.90175 | I31: =+G31/2+J31/2 -> 0.9045 | J31: =+J27/2+J35/2 -> 0.91
C32: 0.65 | D32: =+D31/2+D33/2 -> 0.86 | E32: =+(D32+G32)/2 -> 0.870875 | F32: =+E32/2+G32/2 -> 0.8763125 | G32: =+G31/2+G33/2 -> 0.88175 | H32: =+G32/2+I32/2 -> 0.8849375 | I32: =+G32/2+J32/2 -> 0.888125 | J32: =+J31/2+J33/2 -> 0.8945
C33: 0.7 | D33: =+D31/2+D35/2 -> 0.84 | E33: =+(D33+G33)/2 -> 0.85225 | F33: =+E33/2+G33/2 -> 0.858375 | G33: =+G31/2+G35/2 -> 0.8645 | H33: =+G33/2+I33/2 -> 0.868125 | I33: =+G33/2+J33/2 -> 0.87175 | J33: =+J31/2+J35/2 -> 0.879
C34: =+C33/2+C35/2 -> 0.75 | D34: =+D33/2+D35/2 -> 0.82 | E34: =+(D34+G34)/2 -> 0.833625 | F34: =+E34/2+G34/2 -> 0.8404375 | G34: =+G33/2+G35/2 -> 0.84725 | H34: =+G34/2+I34/2 -> 0.8513125 | I34: =+G34/2+J34/2 -> 0.855375 | J34: =+J33/2+J35/2 -> 0.8635
C35: 0.8 | D35: 0.8 | E35: =+(D35+G35)/2 -> 0.815 | F35: =+E35/2+G35/2 -> 0.8225 | G35: 0.83 | H35: =+G35/2+I35/2 -> 0.8345 | I35: =+G35/2+J35/2 -> 0.839 | J35: 0.848
C36: 0.85 | D36: =+D35/2+D37/2 -> 0.77575 | E36: =+(D36+G36)/2 -> 0.79175 | F36: =+E36/2+G36/2 -> 0.79975 | G36: =+G35/2+G37/2 -> 0.80775 | H36: =+G36/2+I36/2 -> 0.812625 | I36: =+G36/2+J36/2 -> 0.8175 | J36: =+J35/2+J37/2 -> 0.82725
C37: 0.9 | D37: =+D35/2+D39/2 -> 0.7515 | E37: =+(D37+G37)/2 -> 0.7685 | F37: =+E37/2+G37/2 -> 0.777 | G37: =+G35/2+G39/2 -> 0.7855 | H37: =+G37/2+I37/2 -> 0.79075 | I37: =+G37/2+J37/2 -> 0.796 | J37: =+J35/2+J39/2 -> 0.8065
C38: =+C37/2+C39/2 -> 0.95 | D38: =+D37/2+D39/2 -> 0.72725 | E38: =+(D38+G38)/2 -> 0.74525 | F38: =+E38/2+G38/2 -> 0.75425 | G38: =+G37/2+G39/2 -> 0.76325 | H38: =+G38/2+I38/2 -> 0.768875 | I38: =+G38/2+J38/2 -> 0.7745 | J38: =+J37/2+J39/2 -> 0.78575
C39: 1 | D39: =+D43/2+D35/2 -> 0.703 | E39: =+(D39+G39)/2 -> 0.722 | F39: =+E39/2+G39/2 -> 0.7315 | G39: =+G43/2+G35/2 -> 0.741 | H39: =+G39/2+I39/2 -> 0.747 | I39: =+G39/2+J39/2 -> 0.753 | J39: =+J43/2+J35/2 -> 0.765
C40: =+C39/2+C41/2 -> 1.05 | D40: =+D39/2+D41/2 -> 0.67875 | E40: =+(D40+G40)/2 -> 0.69875 | F40: =+E40/2+G40/2 -> 0.70875 | G40: =+G39/2+G41/2 -> 0.71875 | H40: =+G40/2+I40/2 -> 0.725125 | I40: =+G40/2+J40/2 -> 0.7315 | J40: =+J39/2+J41/2 -> 0.74425
C41: 1.1 | D41: =+D39/2+D43/2 -> 0.6545 | E41: =+(D41+G41)/2 -> 0.6755 | F41: =+E41/2+G41/2 -> 0.686 | G41: =+G39/2+G43/2 -> 0.6965 | H41: =+G41/2+I41/2 -> 0.70325 | I41: =+G41/2+J41/2 -> 0.71 | J41: =+J39/2+J43/2 -> 0.7235
C42: =+C41/2+C43/2 -> 1.15 | D42: =+D41/2+D43/2 -> 0.63025 | E42: =+(D42+G42)/2 -> 0.65225 | F42: =+E42/2+G42/2 -> 0.66325 | G42: =+G41/2+G43/2 -> 0.67425 | H42: =+G42/2+I42/2 -> 0.681375 | I42: =+G42/2+J42/2 -> 0.6885 | J42: =+J41/2+J43/2 -> 0.70275
C43: 1.2 | D43: 0.606 | E43: =+(D43+G43)/2 -> 0.629 | F43: =+E43/2+G43/2 -> 0.6405 | G43: 0.652 | H43: =+G43/2+I43/2 -> 0.6595 | I43: =+G43/2+J43/2 -> 0.667 | J43: 0.682
...

Sheet TRANG BIA
A19: ="TÍNH TOÁN MÓNG CỘT " &'N411-20'!C3 -> TÍNH TOÁN MÓNG CỘT D411-25
A21: ="MÓNG " &'N411-20'!J3 -> MÓNG MB 2.6-5x6
D185: =VLOOKUP(J58,'Bảng tra'!$I$3:$M$6,5,0)*100 -> #N/A

Sheet TBA-1
A1: ='N411-20'!A1:B1 -> CÔNG TRÌNH | C1: ='N411-20'!C1:D1 -> NHÀ MÁY ĐIỆN GIÓ
A2: ='N411-20'!A2:B2 -> HẠNG MỤC | C2: ='N411-20'!C2:D2 -> ĐƯỜNG DÂY 22kV | V2: Chú ý: có Ao hay ko, nếu có ghi Ao vào ô V3, Không có thì xóa ô V3 đi
A3: ='N411-20'!A3:B3 -> Cột | C3: ='N411-20'!C3:D3 -> D411-25 | I3: ='N411-20'!I3 -> Loại móng: | J3: ='N411-20'!J3 -> MB 2.6-5x6 | W3: =IF(V3="Ao","A","")
E4: KIỂM TRA NỀN MÓNG | I4: Vị trí: | J4: TBA-1
J6: Kích thước chân cột
J7: L1 = | K7: ='N411-20'!K7 -> 2.6 | L7: (m) | V7: Copy địa chất vào bảng này
J8: L2 = | K8: ='N411-20'!K8 -> 2.6 | L8: (m) | V8: Lớp | W8: Tên lớp | X8: Chiều dày | Y8: γw | Z8: ∆ | AA8: ε0 | AB8: φ | AC8: C | AD8: E
J9: Chọn kích thước móng | X9: (m) | Y9: (T/m³) | AB9: (độ) | AC9: (T/m²) | AD9: (T/m²)
J10: B = | K10: ='N411-20'!K10 -> 5 | L10: (m) | V10: Lớp 1 | W10: Á sét | X10: 2 | Y10: 1.79 | Z10: 2.61 | AA10: 0.61 | AB10: 15 | AC10: 4.7 | AD10: 550
J11: L = | K11: ='N411-20'!K11 -> 6 | L11: (m) | V11: Lớp 1 | W11: Sét | X11: 3 | Y11: 1.83 | Z11: 2.59 | AA11: 0.62 | AB11: 17 | AC11: 5.4 | AD11: 550
J12: L/B = | K12: =+ROUND(K11/K10,2) -> 1.2 | V12: Lớp 1 | W12: Sét | X12: 3 | Y12: 1.85 | Z12: 2.61 | AA12: 0.6 | AB12: 19 | AC12: 5.9 | AD12: 550
J13: Chiều sâu chôn móng
J14: H1 = | K14: ='N411-20'!K14 -> 2.5 | L14: (m) | AA14: `
J15: Chiều cao móng trên mặt đất | W15: `
J16: H2 = | K16: ='N411-20'!K16 -> 1 | L16: (m)
G17: =G26 -> 1.2 | J17: Chiều cao móng
J18: H = | K18: =K14+K16 -> 3.5 | L18: (m)
J19: Bản móng
G20: =K8 -> 2.6 | J20: hb = | K20: ='N411-20'!K20 -> 0.5 | L20: (m) | P20: Ghi chuù | R20: W(kg/m) | S20: F(cm²)
J21: hv = | K21: ='N411-20'!K21 -> 0.3 | L21: (m) | P21: 30 | Q21: =+P21/1000 -> 0.03 | R21: =3.14*Q21^2/4*7850 -> 5.546025 | S21: =3.14*Q21^2/4*10000 -> 7.065
J22: Cổ móng | P22: 28 | Q22: =+P22/1000 -> 0.028 | R22: =3.14*Q22^2/4*7850 -> 4.831204 | S22: =3.14*Q22^2/4*10000 -> 6.1544
J23: b = | K23: ='N411-20'!K23 -> 1 | L23: (m) | P23: 25 | Q23: =+P23/1000 -> 0.025 | R23: =3.14*Q23^2/4*7850 -> 3.8514063 | S23: =3.14*Q23^2/4*10000 -> 4.90625
J24: Các kích thước khác | P24: 22 | Q24: =+P24/1000 -> 0.022 | R24: =3.14*Q24^2/4*7850 -> 2.982529 | S24: =3.14*Q24^2/4*10000 -> 3.7994
J25: la1 = | K25: =K7-K23 -> 1.6 | L25: (m) | P25: 20 | Q25: =+P25/1000 -> 0.02 | R25: =3.14*Q25^2/4*7850 -> 2.4649 | S25: =3.14*Q25^2/4*10000 -> 3.14
G26: =(K10-K7)/2 -> 1.2 | J26: la2 = | K26: =(K10-K7-K23)/2 -> 0.7 | L26: (m) | P26: 18 | Q26: =+P26/1000 -> 0.018 | R26: =3.14*Q26^2/4*7850 -> 1.996569 | S26: =3.14*Q26^2/4*10000 -> 2.5434
J27: lb1 = | K27: =K8-K23 -> 1.6 | L27: (m) | P27: 16 | Q27: =+P27/1000 -> 0.016 | R27: =3.14*Q27^2/4*7850 -> 1.577536 | S27: =3.14*Q27^2/4*10000 -> 2.0096
C28: =F28 -> 1.7 | E28: =K7 -> 2.6 | F28: =(K11-K8)/2 -> 1.7 | J28: lb2 = | K28: =(K11-K8-K23)/2 -> 1.2 | L28: (m) | P28: 14 | Q28: =+P28/1000 -> 0.014 | R28: =3.14*Q28^2/4*7850 -> 1.207801 | S28: =3.14*Q28^2/4*10000 -> 1.5386
A29: 1.Tổ hợp lực chân cột truyền xuống móng | J29: Thể tích bê tông móng | P29: 12 | Q29: =+P29/1000 -> 0.012 | R29: =3.14*Q29^2/4*7850 -> 0.887364 | S29: =3.14*Q29^2/4*10000 -> 1.1304
A30: Bảng tổng hợp nội lực | J30: V = | K30: =K10*K11*K21+(((K10*K11)+(K7+K23+0.2)^2+(K10+K7+K23+0.2)*(K11+K8+K23+0.2))*(K20-K21)/6)+K23*K23*(K18-K20)*4 -> 25.356 | L30: (m³)
A31: Trường hợp | C31: Qx(T) | D31: Qy(T) | E31: N(T) | F31: Mx(T.m) | G31: My(T.m) | H31: Mz(T.m) | J31: Diện tích đáy móng
A32: Lực nhổ max | C32: ='N411-20'!C32 -> -1.6875 | D32: ='N411-20'!D32 -> -1.4111 | E32: ='N411-20'!E32 -> 17.9143 | F32: ='N411-20'!F32 -> -0.0685 | G32: ='N411-20'!G32 -> 0.0464 | H32: ='N411-20'!H32 -> 0.0014 | J32: F = | K32: =K10*K11 -> 30 | L32: (m²)
A33: Lực nén max | C33: ='N411-20'!C33 -> -1.8271 | D33: ='N411-20'!D33 -> -1.8968 | E33: ='N411-20'!E33 -> -20.9922 | F33: ='N411-20'!F33 -> -0.0597 | G33: ='N411-20'!G33 -> 0.0767 | H33: ='N411-20'!H33 -> 0.001 | L33: Mômen kháng đáy móng theo phương X
A34: Tải trọng quy tâm | B34: 90 độ max | C34: ='N411-20'!C34 -> -2.5344 | D34: ='N411-20'!D34 -> -1.7965 | E34: ='N411-20'!E34 -> 6.395 | F34: ='N411-20'!F34 -> 26.65408 | G34: ='N411-20'!G34 -> 47.4663 | H34: ='N411-20'!H34 -> 0.293136 | J34: Wx = | K34: =(K11*K10^3)/6/K10 -> 25 | L34: (m³)
B35: 45 độ max | C35: ='N411-20'!C35 -> -2.4744 | D35: ='N411-20'!D35 -> -2.9365 | E35: ='N411-20'!E35 -> 6.1551 | F35: ='N411-20'!F35 -> 55.32799 | G35: ='N411-20'!G35 -> 45.79901 | H35: ='N411-20'!H35 -> 0.407518 | L35: Mômen kháng đáy móng theo phương Y
B36: Sự cố max | C36: ='N411-20'!C36 -> -2.4744 | D36: ='N411-20'!D36 -> -2.9365 | E36: ='N411-20'!E36 -> 6.1551 | F36: ='N411-20'!F36 -> 55.32799 | G36: ='N411-20'!G36 -> 45.79901 | H36: ='N411-20'!H36 -> 0.407518 | J36: Wy = | K36: =+(K10*K11^3)/12/K11*2 -> 30 | L36: (m³)
B37: TXTC | C37: ='N411-20'!C37 -> -1.15 | D37: ='N411-20'!D37 -> 0 | E37: ='N411-20'!E37 -> 5.6477 | F37: ='N411-20'!F37 -> -0.23857 | G37: ='N411-20'!G37 -> 27.86171 | H37: ='N411-20'!H37 -> 0.073859
A38: Giá trị tiêu chuẩn
A39: Gió 900 max | B39: Ntc = | C39: ='N411-20'!C40/1.15 -> 5.5608696 | D39: (T) | P39: 10 | Q39: =+P39/1000 -> 0.01 | R39: =3.14*Q39^2/4*7850 -> 0.616225 | S39: =3.14*Q39^2/4*10000 -> 0.785
B40: Qtcx = | C40: ='N411-20'!C41/1.15 -> 2.2038261 | D40: (T) | E40: Qtcy = | F40: ='N411-20'!F41/1.15 -> 1.5621739 | G40: (T) | P40: 8 | Q40: =+P40/1000 -> 0.008 | R40: =3.14*Q40^2/4*7850 -> 0.394384 | S40: =3.14*Q40^2/4*10000 -> 0.5024
B41: Mtcy = | C41: ='N411-20'!C42/1.15 -> 41.275043 | D41: (T.m) | E41: Mtcx = | F41: ='N411-20'!F42/1.15 -> 23.177461 | G41: (T.m) | J41: Thể tích đất lấp móng | P41: 6 | Q41: =+P41/1000 -> 0.006 | R41: =3.14*Q41^2/4*7850 -> 0.221841 | S41: =3.14*Q41^2/4*10000 -> 0.2826
...

Sheet N411-20
A1: CÔNG TRÌNH | C1: NHÀ MÁY ĐIỆN GIÓ | N1: =J3 -> MB 2.6-5x6
A2: HẠNG MỤC | C2: ĐƯỜNG DÂY 22kV | M2: MÃ DỰ ÁN: | N2: 18105TBH.T.I3.C2.2. | P2: Luôn kiểm tra mã dự án
A3: Cột | C3: =O6 -> D411-25 | I3: Loại móng: | J3: =+"MB "&K7&"-"&K10&"x"&K11 -> MB 2.6-5x6 | M3: GIAI ĐOẠN TK | N3: TKBVTC | O3: Chú ý chọn giai đoạn TK vì liên quan đến khối lượng
E4: KIỂM TRA KẾT CẤU MÓNG | N4: Copy giá trị nội lực
J6: Kích thước chân cột | N6: LOẠI CỘT | O6: D411-25 | P6: TỔ HỢP LỰC TÍNH TOÁN (ĐƠN VỊ: T-Tm)
J7: L1 = | K7: =O7/1000 -> 2.6 | L7: (m) | N7: 2600 | O7: =N7 -> 2600 | P7: Qx (T) | Q7: Qy (T) | R7: N (T) | S7: Mx (T.m) | T7: My (T.m) | U7: Mz (T.m)
J8: L2 = | K8: =+K7 -> 2.6 | L8: (m) | M8: =4.8*5.4*0.1 -> 2.592 | N8: Từng chân | O8: Lực nhổ max | P8: -1.6875 | Q8: -1.4111 | R8: 17.9143 | S8: -0.0685 | T8: 0.0464 | U8: 0.0014
J9: Chọn kích thước móng | O9: Lực nén máx | P9: -1.8271 | Q9: -1.8968 | R9: -20.9922 | S9: -0.0597 | T9: 0.0767 | U9: 0.001
J10: B = | K10: 5 | L10: (m) | M10: B: Chiều rộng móng | N10: Cả cột | O10: 90o max | P10: -2.5344 | Q10: -1.7965 | R10: 6.395 | S10: 26.65408 | T10: 47.4663 | U10: 0.293136
J11: L = | K11: 6 | L11: (m) | M11: L:Chiều dài móng | O11: 45o max | P11: -2.4744 | Q11: -2.9365 | R11: 6.1551 | S11: 55.32799 | T11: 45.79901 | U11: 0.407518
J12: L/B = | K12: =+ROUND(K11/K10,2) -> 1.2 | O12: Sự cố max | P12: -2.4744 | Q12: -2.9365 | R12: 6.1551 | S12: 55.32799 | T12: 45.79901 | U12: 0.407518
J13: Chiều sâu chôn móng | O13: TXTC | P13: -1.15 | Q13: 0 | R13: 5.6477 | S13: -0.23857 | T13: 27.86171 | U13: 0.073859
J14: H1 = | K14: 2.5 | L14: (m)
J15: Chiều cao móng trên mặt đất | N15: Modun đàn hồi của bê tông Eb (10^3 Mpa) | R15: 1Mpa =100T/m2
J16: H2 = | K16: 1 | L16: (m) | N16: B12.5 | O16: B15 | P16: B20 | Q16: B25 | R16: B30 | S16: B35 | T16: B40
G17: =G26 -> 1.2 | J17: Chiều cao móng | N17: 21 | O17: 23 | P17: 27 | Q17: 30 | R17: 32.5 | S17: 34.5 | T17: 36
J18: H = | K18: =K14+K16 -> 3.5 | L18: (m) | M18: T/m2 | N18: =N17*100*1000 -> 2100000 | O18: =O17*100*1000 -> 2300000 | P18: =P17*100*1000 -> 2700000 | Q18: =Q17*100*1000 -> 3000000 | R18: =R17*100*1000 -> 3250000 | S18: =S17*100*1000 -> 3450000 | T18: =T17*100*1000 -> 3600000
J19: Bản móng
G20: =K8 -> 2.6 | J20: hb = | K20: 0.5 | L20: (m) | M20: Dầm móng
J21: hv = | K21: 0.3 | L21: (m) | M21: a = | N21: =K23 -> 1 | O21: (m)
J22: Cổ móng | M22: h = | N22: =K20 -> 0.5 | O22: (m) | P22: 28 | Q22: =+P22/1000 -> 0.028 | R22: =3.14*Q22^2/4*7850 -> 4.831204 | S22: =3.14*Q22^2/4*10000 -> 6.1544
J23: b = | K23: 1 | L23: (m) | M23: e = | N23: =K23/2 -> 0.5 | O23: (m) | P23: 25 | Q23: =+P23/1000 -> 0.025 | R23: =3.14*Q23^2/4*7850 -> 3.8514063 | S23: =3.14*Q23^2/4*10000 -> 4.90625
J24: Các kích thước khác | P24: 22 | Q24: =+P24/1000 -> 0.022 | R24: =3.14*Q24^2/4*7850 -> 2.982529 | S24: =3.14*Q24^2/4*10000 -> 3.7994
J25: la1 = | K25: =K7-K23 -> 1.6 | L25: (m) | O25: ` | P25: 20 | Q25: =+P25/1000 -> 0.02 | R25: =3.14*Q25^2/4*7850 -> 2.4649 | S25: =3.14*Q25^2/4*10000 -> 3.14
G26: =(K10-K7)/2 -> 1.2 | J26: la2 = | K26: =(K10-K7-K23)/2 -> 0.7 | L26: (m) | P26: 18 | Q26: =+P26/1000 -> 0.018 | R26: =3.14*Q26^2/4*7850 -> 1.996569 | S26: =3.14*Q26^2/4*10000 -> 2.5434
J27: lb1 = | K27: =K8-K23 -> 1.6 | L27: (m) | P27: 16 | Q27: =+P27/1000 -> 0.016 | R27: =3.14*Q27^2/4*7850 -> 1.577536 | S27: =3.14*Q27^2/4*10000 -> 2.0096
C28: =F28 -> 1.7 | E28: =K7 -> 2.6 | F28: =(K11-K8)/2 -> 1.7 | J28: lb2 = | K28: =(K11-K8-K23)/2 -> 1.2 | L28: (m) | P28: 14 | Q28: =+P28/1000 -> 0.014 | R28: =3.14*Q28^2/4*7850 -> 1.207801 | S28: =3.14*Q28^2/4*10000 -> 1.5386
A29: 1.Tổ hợp lực chân cột truyền xuống móng | J29: Thể tích bê tông móng | P29: 12 | Q29: =+P29/1000 -> 0.012 | R29: =3.14*Q29^2/4*7850 -> 0.887364 | S29: =3.14*Q29^2/4*10000 -> 1.1304
A30: Bảng tổng hợp nội lực | J30: V = | K30: =K10*K11*K21+(((K10*K11)+(K7+K23+0.2)^2+(K10+K7+K23+0.2)*(K11+K8+K23+0.2))*(K20-K21)/6)+K23*K23*(K18-K20)*4 -> 25.356 | L30: (m³) | P30: 10 | Q30: =+P30/1000 -> 0.01 | R30: =3.14*Q30^2/4*7850 -> 0.616225 | S30: =3.14*Q30^2/4*10000 -> 0.785
A31: Trường hợp | C31: Qx(T) | D31: Qy(T) | E31: N(T) | F31: Mx(T.m) | G31: My(T.m) | H31: Mz(T.m) | J31: Diện tích đáy móng | P31: 8 | Q31: =+P31/1000 -> 0.008 | R31: =3.14*Q31^2/4*7850 -> 0.394384 | S31: =3.14*Q31^2/4*10000 -> 0.5024
A32: Lực nhổ max | C32: =P8 -> -1.6875 | D32: =Q8 -> -1.4111 | E32: =R8 -> 17.9143 | F32: =S8 -> -0.0685 | G32: =T8 -> 0.0464 | H32: =U8 -> 0.0014 | J32: F = | K32: =K10*K11 -> 30 | L32: (m²) | P32: 6 | Q32: =+P32/1000 -> 0.006 | R32: =3.14*Q32^2/4*7850 -> 0.221841 | S32: =3.14*Q32^2/4*10000 -> 0.2826
A33: Lực nén max | C33: =P9 -> -1.8271 | D33: =Q9 -> -1.8968 | E33: =R9 -> -20.9922 | F33: =S9 -> -0.0597 | G33: =T9 -> 0.0767 | H33: =U9 -> 0.001 | L33: Mômen kháng đáy móng theo phương X
A34: Tải trọng quy tâm | B34: 90 độ max | C34: =P10 -> -2.5344 | D34: =Q10 -> -1.7965 | E34: =R10 -> 6.395 | F34: =S10 -> 26.65408 | G34: =T10 -> 47.4663 | H34: =U10 -> 0.293136 | J34: Wx = | K34: =(K11*K10^3)/6/K10 -> 25 | L34: (m³)
B35: 45 độ max | C35: =P11 -> -2.4744 | D35: =Q11 -> -2.9365 | E35: =R11 -> 6.1551 | F35: =S11 -> 55.32799 | G35: =T11 -> 45.79901 | H35: =U11 -> 0.407518 | L35: Mômen kháng đáy móng theo phương Y
B36: Sự cố max | C36: =P12 -> -2.4744 | D36: =Q12 -> -2.9365 | E36: =R12 -> 6.1551 | F36: =S12 -> 55.32799 | G36: =T12 -> 45.79901 | H36: =U12 -> 0.407518 | J36: Wy = | K36: =+(K10*K11^3)/12/K11*2 -> 30 | L36: (m³)
B37: TXTC | C37: =P13 -> -1.15 | D37: =Q13 -> 0 | E37: =R13 -> 5.6477 | F37: =S13 -> -0.23857 | G37: =T13 -> 27.86171 | H37: =U13 -> 0.073859
A39: Giá trị tính toán
A40: Gió 900 max | B40: Ntt = | C40: =E34 -> 6.395 | D40: (T)
B41: Qttx = | C41: =ABS(C34) -> 2.5344 | D41: (T) | E41: Qtcy = | F41: =ABS(D34) -> 1.7965 | G41: (T) | J41: Thể tích đất lấp móng
B42: Mtty = | C42: =ABS(G34) -> 47.4663 | D42: (T.m) | E42: Mtcx = | F42: =ABS(F34) -> 26.65408 | G42: (T.m) | J42: V1 = | K42: =K10*K11*K14-K30 -> 49.644 | L42: (m³)
...

Sheet ChiTiet
B2: =+"BẢNG KÊ THÉP MÓNG MB"&Tra!C121&"-"&Tra!C122&"x"&Tra!E122 -> #REF!
B3: SỐ HIỆU | C3: HÌNH DÁNH THANH | K3: Ø (mm) | M3: CHIỀU DÀI 01 THANH (mm) | N3: SỐ LƯỢNG | O3: CHIỀU DÀI TỔNG CỘNG (m) | P3: TỔNG HỢP KHỐI LƯỢNG THÉP CHO 01 MÓNG
P4: Ø (mm) | R4: CHIỀU DÀI (m) | S4: KHỐI LƯỢNG (kg) | T4: KHỐI LƯỢNG TỔNG CỘNG (kg)
B5: =+Tra!I143 -> 1 | K5: =+Tra!J143 -> #REF! | L5: =+IF(K5>=12,"AIII","AI") -> #REF! | M5: =+D6+C6 -> #REF! | N5: =+Tra!L143 -> #REF! | O5: =+N5*M5/1000 -> #REF! | P5: 25 | Q5: =+IF(P5>=12,"AIII","AI") -> AIII | R5: =+SUMIF($K$5:$K$66,P5,$O$5:$O$66) -> 0 | S5: =+ROUND(ROUND(P5^2*3.14/4/1000000*7850,3)*R5,2) -> 0 | T5: =+SUM(S5:S17) -> #REF!
C6: 250 | D6: =+Tra!K143*1000-C6 -> #REF!
B8: =+Tra!I144 -> 2 | D8: =+Tra!K144*1000 -> #REF! | K8: =+Tra!J144 -> #REF! | L8: =+IF(K8>=12,"AIII","AI") -> #REF! | M8: =+D8 -> #REF! | N8: =+Tra!L144 -> #REF! | O8: =+N8*M8/1000 -> #REF! | P8: 16 | Q8: =+IF(P8>=12,"AIII","AI") -> AIII | R8: =+SUMIF($K$5:$K$66,P8,$O$5:$O$66) -> 0 | S8: =+ROUND(ROUND(P8^2*3.14/4/1000000*7850,3)*R8,2) -> 0
B10: =+Tra!I145 -> 2a | D10: =+Tra!K145*1000 -> #REF! | K10: =+Tra!J145 -> #REF! | L10: =+IF(K10>=12,"AIII","AI") -> #REF! | M10: =+D10 -> #REF! | N10: =+Tra!L145 -> 0 | O10: =+N10*M10/1000 -> #REF! | P10: 14 | Q10: =+IF(P10>=12,"AIII","AI") -> AIII | R10: =+SUMIF($K$5:$K$66,P10,$O$5:$O$66) -> 0 | S10: =+ROUND(ROUND(P10^2*3.14/4/1000000*7850,3)*R10,2) -> 0
B12: =+Tra!I146 -> #REF! | D12: =+Tra!K146*1000 -> #REF! | K12: =+Tra!J146 -> #REF! | L12: =+IF(K12>=12,"AIII","AI") -> #REF! | M12: =+D12 -> #REF! | N12: =+Tra!L146 -> #REF! | O12: =+N12*M12/1000 -> #REF! | P12: 12 | Q12: =+IF(P12>=12,"AIII","AI") -> AIII | R12: =+SUMIF($K$5:$K$66,P12,$O$5:$O$66) -> 0 | S12: =+ROUND(ROUND(P12^2*3.14/4/1000000*7850,3)*R12,2) -> 0
B14: =+Tra!I147 -> 3a | D14: =+Tra!K147*1000 -> #REF! | K14: =+Tra!J147 -> #REF! | L14: =+IF(K14>=12,"AIII","AI") -> #REF! | M14: =+D14 -> #REF! | N14: =+Tra!L147 -> 0 | O14: =+N14*M14/1000 -> #REF! | P14: 10 | Q14: =+IF(P14>=12,"AIII","AI") -> AI | R14: =+SUMIF($K$5:$K$66,P14,$O$5:$O$66) -> #REF! | S14: =+ROUND(ROUND(P14^2*3.14/4/1000000*7850,3)*R14,2) -> #REF!
B16: =+Tra!I148 -> 4 | D16: =+Tra!K148*1000 -> #REF! | K16: =+Tra!J148 -> #REF! | L16: =+IF(K16>=12,"AIII","AI") -> #REF! | M16: =+D16 -> #REF! | N16: =+Tra!L148 -> #REF! | O16: =+N16*M16/1000 -> #REF! | P16: 8 | Q16: =+IF(P16>=12,"AIII","AI") -> AI | R16: =+SUMIF($K$5:$K$66,P16,$O$5:$O$66) -> 0 | S16: =+ROUND(ROUND(P16^2*3.14/4/1000000*7850,3)*R16,2) -> 0
B18: =+Tra!I149 -> 4a | D18: =+Tra!K149*1000 -> #REF! | K18: =+Tra!J149 -> #REF! | L18: =+IF(K18>=12,"AIII","AI") -> #REF! | M18: =+D18 -> #REF! | N18: =+Tra!L149 -> #REF! | O18: =+N18*M18/1000 -> #REF!
B20: =+Tra!I150 -> 4b | D20: =+Tra!K150*1000 -> #REF! | K20: =+Tra!J150 -> #REF! | L20: =+IF(K20>=12,"AIII","AI") -> #REF! | M20: =+D20 -> #REF! | N20: =+Tra!L150 -> #REF! | O20: =+N20*M20/1000 -> #REF!
B22: =+Tra!I151 -> 4c | D22: =+Tra!K151*1000 -> #REF! | K22: =+Tra!J151 -> #REF! | L22: =+IF(K22>=12,"AIII","AI") -> #REF! | M22: =+D22 -> #REF! | N22: =+Tra!L151 -> #REF! | O22: =+N22*M22/1000 -> #REF!
B24: =+Tra!I152 -> 4d | D24: =+Tra!K152*1000 -> 0 | K24: =+Tra!J152 -> #REF! | L24: =+IF(K24>=12,"AIII","AI") -> #REF! | M24: =+D24 -> 0 | N24: =+Tra!L152 -> #REF! | O24: =+N24*M24/1000 -> #REF!
B26: =+Tra!I153 -> 4e | D26: =+Tra!K153*1000 -> 0 | K26: =+Tra!J153 -> #REF! | L26: =+IF(K26>=12,"AIII","AI") -> #REF! | M26: =+D26 -> 0 | N26: =+Tra!L153 -> #REF! | O26: =+N26*M26/1000 -> #REF!
B28: =+Tra!I154 -> 5 | D28: =+Tra!K154*1000 -> #REF! | K28: =+Tra!J154 -> #REF! | L28: =+IF(K28>=12,"AIII","AI") -> #REF! | M28: =+D28 -> #REF! | N28: =+Tra!L154 -> #REF! | O28: =+N28*M28/1000 -> #REF!
B30: =+Tra!I155 -> 5a | D30: =+Tra!K155*1000 -> #REF! | K30: =+Tra!J155 -> #REF! | L30: =+IF(K30>=12,"AIII","AI") -> #REF! | M30: =+D30 -> #REF! | N30: =+Tra!L155 -> #REF! | O30: =+N30*M30/1000 -> #REF!
B32: =+Tra!I156 -> 5b | D32: =+Tra!K156*1000 -> #REF! | K32: =+Tra!J156 -> #REF! | L32: =+IF(K32>=12,"AIII","AI") -> #REF! | M32: =+D32 -> #REF! | N32: =+Tra!L156 -> #REF! | O32: =+N32*M32/1000 -> #REF!
B34: =+Tra!I157 -> 5c | D34: =+Tra!K157*1000 -> #REF! | K34: =+Tra!J157 -> #REF! | L34: =+IF(K34>=12,"AIII","AI") -> #REF! | M34: =+D34 -> #REF! | N34: =+Tra!L157 -> #REF! | O34: =+N34*M34/1000 -> #REF!
B36: =+Tra!I158 -> 5d | D36: =+Tra!K158*1000 -> 0 | K36: =+Tra!J158 -> #REF! | L36: =+IF(K36>=12,"AIII","AI") -> #REF! | M36: =+D36 -> 0 | N36: =+Tra!L158 -> #REF! | O36: =+N36*M36/1000 -> #REF!
B38: =+Tra!I159 -> 5e | D38: =+Tra!K159*1000 -> 0 | K38: =+Tra!J159 -> #REF! | L38: =+IF(K38>=12,"AIII","AI") -> #REF! | M38: =+Tra!K159*1000 -> 0 | N38: =+Tra!L159 -> #REF! | O38: =+N38*M38/1000 -> #REF!
B40: =+Tra!I160 -> 6 | D40: =+Tra!K160*1000 -> #REF! | K40: =+Tra!J160 -> #REF! | L40: =+IF(K40>=12,"AIII","AI") -> #REF! | M40: =+D40 -> #REF! | N40: =+Tra!L160 -> #REF! | O40: =+N40*M40/1000 -> #REF!
B42: =+Tra!I161 -> 7 | D42: =+Tra!K161*1000 -> #REF! | K42: =+Tra!J161 -> #REF! | L42: =+IF(K42>=12,"AIII","AI") -> #REF! | M42: =+D42 -> #REF! | N42: =+Tra!L161 -> #REF! | O42: =+N42*M42/1000 -> #REF!
B44: =+Tra!I162 -> 8 | K44: =+Tra!J162 -> 10 | L44: =+IF(K44>=12,"AIII","AI") -> AI | M44: =+J45+D45+C45 -> #REF! | N44: =+Tra!L162 -> #REF! | O44: =+N44*M44/1000 -> #REF!
C45: 50 | D45: =+Tra!N162*1000 -> #REF! | J45: 50
B47: =+Tra!I163 -> 9 | K47: =+Tra!J163 -> 10 | L47: =+IF(K47>=12,"AIII","AI") -> AI | M47: =+(E49*2+D49*2+H48*2) -> #REF! | N47: =+Tra!L163 -> #REF! | O47: =+N47*M47/1000 -> #REF!
H48: 60
D49: =+Tra!N163*1000 -> #REF! | E49: =+Tra!O163*1000 -> #REF!
B51: =+Tra!I164 -> 9a | K51: =+Tra!J164 -> 10 | L51: =+IF(K51>=12,"AIII","AI") -> AI | M51: =+(E53*2+D53*2+H52*2) -> #REF! | N51: =+Tra!L164 -> #REF! | O51: =+N51*M51/1000 -> #REF!
H52: 60
D53: =+Tra!N164*1000 -> 350 | E53: =+Tra!O164*1000 -> #REF!
B55: =+Tra!I165 -> 9b | C55: 60 | D55: =+Tra!N165*1000 -> #REF! | J55: 60 | K55: =+Tra!J165 -> 10 | L55: =+IF(K55>=12,"AIII","AI") -> AI | M55: =+D55+J55*2 -> #REF! | N55: =+Tra!L165 -> #REF! | O55: =+N55*M55/1000 -> #REF!
B57: =+Tra!I166 -> 10 | K57: =+Tra!J166 -> 10 | L57: =+IF(K57>=12,"AIII","AI") -> AI | M57: =+F59*4+G58*2 -> #REF! | N57: =+Tra!L166 -> #REF! | O57: =+N57*M57/1000 -> #REF!
G58: 60
E59: =+F59 -> #REF! | F59: =+Tra!N166*1000 -> #REF!
B61: =+Tra!I167 -> 11 | K61: =+Tra!J167 -> 10 | L61: =+IF(K61>=12,"AIII","AI") -> AI | M61: =+F63*4+G62*2 -> 3720 | N61: =+Tra!L167 -> #REF! | O61: =+N61*M61/1000 -> #REF!
G62: 60
E63: =+F63 -> 900 | F63: =+Tra!N167*1000 -> 900
B65: =+Tra!I168 -> 12 | C65: 60 | D65: =+Tra!N168*1000 -> #REF! | J65: 60 | K65: =+Tra!J168 -> 10 | L65: =+IF(K65>=12,"AIII","AI") -> AI | M65: =+D65+J65*2 -> #REF! | N65: =+Tra!L168 -> #REF! | O65: =+N65*M65/1000 -> #REF!
B70: =+Tra!I167 -> 11 | E70: =+Tra!O167*1000 -> 0 | K70: =+Tra!J167 -> 10 | L70: =+IF(K70>=12,"AIII","AI") -> AI | M70: =+E71*2+E70*2+H71*2 -> 1920 | N70: =+Tra!L167 -> #REF! | O70: =+N70*M70/1000 -> #REF!
...

Sheet TONG HOP
A2: Giai đoạn thiết kế | C2: TKBVTC | J2: Bê tông móng: | K2: =LEFT('N411-20'!D58,3) -> B20
A3: HÌNH THỨC MÓNG CỘT | C3: NÉO GÓC | D3: ='N411-20'!C3 -> D411-25 | J3: Bê tông lót: | K3: B7.5
A4: MÓNG | B4: ='N411-20'!J3 -> MB 2.6-5x6 | J4: Mã bản vẽ Ghi chú chung: | K4: 2511TNC2.F.NM.C.200
J6: Kích thước chân cột
J7: L1 = | K7: ='N411-20'!$K$7 -> 2.6 | L7: (m)
J8: L2 = | K8: =+K7 -> 2.6 | L8: (m)
J9: Chọn kích thước móng
J10: B = | K10: ='N411-20'!$K$10 -> 5 | L10: (m)
G11: 0.1 | J11: L = | K11: ='N411-20'!$K$11 -> 6 | L11: (m)
J13: Chiều sâu chôn móng
J14: H1 = | K14: ='N411-20'!$K$14 -> 2.5 | L14: (m)
J15: Chiều cao móng trên mặt đất
J16: H2 = | K16: ='N411-20'!$K$16 -> 1 | L16: (m)
G17: =G26 -> 1.2 | J17: Chiều cao móng
J18: H= H1 + H2 = | K18: =K14+K16 -> 3.5 | L18: (m)
J19: Bản móng
J20: hb = | K20: ='N411-20'!$K$20 -> 0.5 | L20: (m)
J21: hv = | K21: ='N411-20'!$K$21 -> 0.3 | L21: (m)
G22: =K8 -> 2.6 | J22: Cổ móng
J23: b = | K23: ='N411-20'!$K$23 -> 1 | L23: (m)
J25: Đệm cát
G26: =(K10-K7)/2 -> 1.2 | J26: h đệm cát | K26: 0.5 | L26: (m)
J27: Hệ số mở mái | K27: =IF(K26=0,0.5,IF(K14+K26+0.1>3.1,1.25,1)) -> 1 | L27: (m)
C28: =F28 -> 1.7 | E28: =K7 -> 2.6 | F28: =(K11-K8)/2 -> 1.7 | J28: Mở rộng đáy hố đào | K28: =IF(K26>0.5,0.6,0.3) -> 0.3 | L28: (m)
J29: Bu lông neo | K29: BLN- | L29: M36-250
A30: Thép bản móng | C30: đường kính | D30: bước thép | J30: Chiều dày lớp bê tông bảo vệ
B31: Lớp dưới | C31: ='N411-20'!C98 -> 12 | D31: ='N411-20'!E98*10 -> 200 | E31: (mm) | J31: Đáy móng | K31: ='N411-20'!F94*1000 -> 50 | L31: (mm)
B32: Lớp trên | C32: =C31 -> 12 | D32: =D31 -> 200 | E32: (mm) | J32: Vị trí còn lại | K32: =K31 -> 50 | L32: (mm)
B33: Thép chống | C33: =C32 -> 12 | D33: =D32*3 -> 600 | E33: (mm)
A34: Thép cổ móng | C34: đường kính | D34: số lượng/ bước thép
B35: Thép chủ | C35: ='N411-20'!C232 -> 20 | D35: ='N411-20'!E232*2+('N411-20'!E232-2)*2 -> 36
B36: Thép đai | C36: 8 | D36: 200 | E36: (mm)
B37: Đai phụ | C37: =C36 -> 8 | D37: =D36*2 -> 400 | E37: (mm)
B38: Lưới đầu trụ | C38: =C36 -> 8 | D38: =D36/2 -> 100 | E38: (mm) | F38: 02 lớp

Sheet KL
A1: THỐNG KÊ MÓNG | U1: BẢNG TỔNG HỢP VẬT LIỆU MÓNG (01 MÓNG)
A2: Tên công trình: | D2: ='[1]N411-20'!C1 -> NHÀ MÁY ĐIỆN GIÓ | K2: OUTPUT 1: | M2: BẢNG KÊ KHỐI LƯỢNG | U2: THỂ TÍCH BÊ TÔNG (m³) | W2: KHỐI LƯỢNG CỐT THÉP (kg) | AA2: TỔNG K.LƯỢNG THÉP (kg) | AB2: BU LÔNG NEO (bộ)
A3: Hạng mục: | D3: Móng | E3: ='[1]N411-20'!J3 -> MB 2.6-4.6x5.2 | G3: Cột: | H3: ='[1]N411-20'!C3 -> D411-25 | K3: STT | L3: HẠNG MỤC | P3: ĐƠN VỊ | Q3: K.LƯỢNG | S3: Cột | T3: Móng | U3: B20 (M250) | V3: B7.5 (M100) | W3: Ø8 | X3: Ø12 | Y3: Ø16 | Z3: Ø20 | AC3: Đất đào | AD3: Đất đắp | AE3: Cốp pha
K4: 1 | L4: BÊ TÔNG LÓT MÓNG ĐÁ 4x6 MÁC 100 | P4: m3 | Q4: =((B10+0.2)*(B11+0.2)*B23/1000) -> 2.592 | S4: =H3 -> D411-25 | U4: =Q5 -> 12.724 | V4: =Q4 -> 2.592 | W4: =K38 -> 271.41655 | X4: =M38 -> 212.16762 | Y4: - | Z4: =N38 -> 307.0704 | AA4: =Q8 -> 790.65457 | AB4: 16 M36 | AC4: =Q10 -> 121.45467 | AD4: =Q11 -> 107.57867 | AE4: =R36+R38 -> 33.68
K5: 2 | L5: BÊ TÔNG CẤU KIỆN ĐÁ 2x4 MÁC 200 | P5: m3 | Q5: =Q6+Q7 -> 12.724 | AA5: 1 trụ | AB5: hết móng
L6: 2.1 | M6: ĐÀI CỌC | P6: m3 | Q6: =((B10*B11+(B14+D15+0.2)^2+(B10+B14+D15+0.2)*(B11+B14+D15+0.2))*(B16-B17)/6+B17*B10*B11) -> 8.26 | Z6: a = | AA6: =B10+0.6 -> 5.2 | AB6: =B14+B11+2*0.3 -> 8.4 | AC6: m
L7: 2.2 | M7: CỔ MÓNG | P7: m3 | Q7: =4*((D15^2+B15^2+(D15+B15)^2)*(B12+B13-B16)/6) -> 4.464 | Z7: b = | AA7: =B11+0.6 -> 5.8 | AB7: =B14+B10+2*0.3 -> 7.8 | AC7: m
A8: INPUT | K8: 3 | L8: CỐT THÉP TRÒN CÁC LOẠI | P8: kg | Q8: =+IF(SUM(K38:O38)=(1+0.01*R35)*SUM(R16:R34),SUM(K38:O38),"Chưa được") -> 790.65457 | Z8: c = | AA8: =AA6+2*AA10*E26 -> 7.8 | AB8: =AB6+2*AB10*E26 -> 11 | AC8: m
A9: Kích thước móng | F9: Ghi chú | K9: 4 | L9: ="BU LÔNG NEO "&[2]TINH_TOAN!F114 -> BU LÔNG NEO M36 | P9: bộ | Z9: d = | AA9: =AA7+2*AA10*E26 -> 8.4 | AB9: =AB7+2*AB10*E26 -> 10.4 | AC9: m
A10: Bm = | B10: ='[1]N411-20'!K10 -> 4.6 | C10: m | F10: dọc theo phương chịu lực | K10: 5 | L10: ĐẤT ĐÀO | M10: ="("&IF(AND(J10>0,J11>0),"Đào từng chân trụ","Đào hết móng")&")" -> (Đào hết móng) | P10: m3 | Q10: =IF(J10<0,AB11,AA11*E25) -> 121.45467 | Z10: H = | AA10: =B12+B23/1000 -> 2.6 | AB10: =AA10 -> 2.6 | AC10: m
A11: Lm = | B11: ='[1]N411-20'!K11 -> 5.2 | C11: m | F11: vuông góc với phương chịu lực | K11: 6 | L11: ĐẤT ĐẮP | P11: m3 | Q11: =+Q10-Q4-Q5+4*(B15^2+(B15+(D15-B15)*B13/(B12+B13-B16))^2+(B15+(B15+(D15-B15)*B13/(B12+B13-B16)))^2)*B13/6 -> 107.57867 | Z11: V = | AA11: =(AA6*AA7+AA8*AA9+(AA6+AA8)*(AA7+AA9))*AA10/6 -> 121.45467 | AB11: =(AB6*AB7+AB8*AB9+(AB6+AB8)*(AB7+AB9))*AB10/6 -> 230.96667 | AC11: m3
A12: Hm = | B12: ='[1]N411-20'!K14 -> 2.5 | C12: m | F12: chiều sâu chôn móng
A13: d = | B13: ='[1]N411-20'!K16 -> 1 | C13: m | F13: ch.cao cổ móng tính từ mặt đất
A14: Bt = | B14: ='[1]N411-20'!K7 -> 2.6 | C14: m | F14: khoảng cách trục móng | J14: OUTPUT 2: | K14: BẢNG KÊ THÉP (CHO 1 BẢN MÓNG)
A15: bc = hc = | B15: ='[1]N411-20'!K23 -> 0.6 | C15: m | D15: =B15 -> 0.6 | E15: m | F15: bề rộng cổ móng | J15: Vị trí | K15: Hình dạng và kích thước (mm) | N15: f (mm) | O15: Chiều dài (mm) | P15: Số lượng | Q15: Tổng c.dài (m) | R15: KL (kg)
A16: hb = | B16: ='[1]N411-20'!K20 -> 0.4 | C16: m | F16: chiều cao đài móng | J16: 1 | L16: =+B10*1000-C28*2 -> 4500 | N16: =C18 -> 12 | O16: =+K16+L16+M16 -> 4500 | P16: =H60 -> 23 | Q16: =((P16*O16)/1000) -> 103.5 | R16: =+VLOOKUP(N16,CT,3,0)*Q16 -> 91.908 | S16: Thanh dọc trong đài (lớp dưới) | AG16: 1 chân móng
A17: hv = | B17: ='[1]N411-20'!K21 -> 0.2 | C17: m | F17: chiều cao mép đài móng | K17: =ROUND(D85,-1) -> 490 | L17: =ROUND(C85,-1) -> 3580 | AD17: taluy | AE17: =IF(AE21<3, 0.25,0.5) -> 0.25 | AF17: Đất đào | AG17: =((AG29*AG29+AF20*AF20+(AG29+AF20)*(AG29+AF20))*AE21/6)*4 -> 318.18667
A18: thép đài | B18: f | C18: ='[1]N411-20'!C98 -> 12 | D18: @ | E18: ='[1]N411-20'!E98*10 -> 200 | J18: 2 | K18: =B17*1000-(F28+C28) -> 100 | M18: =K18 -> 100 | N18: =N16 -> 12 | O18: =L17+2*(K18+K17) -> 4760 | P18: =P16 -> 23 | Q18: =((P18*O18)/1000) -> 109.48 | R18: =+VLOOKUP(N18,CT,3,0)*Q18 -> 97.21824 | S18: Thanh dọc trong đài (lớp trên) | AF18: Đục đá | AG18: =(AH28*AH28*(AE25+0.1))*4 -> 75.712
A19: th.đài chống | B19: f | C19: =C18 -> 12 | D19: @ | E19: =E18*3 -> 600 | AF19: Đất đắp | AG19: =+AG17+AG18-Q4-Q5+4*(B15^2+(B15+(D15-B15)*B13/(B12+B13-B16))^2+(B15+(B15+(D15-B15)*B13/(B12+B13-B16)))^2)*B13/6 -> 380.02267
A20: thép cột | C20: =('[1]N411-20'!E232-1)*4 -> 8 | D20: f | E20: ='[1]N411-20'!C232 -> 20 | F20: tính cho cả 4 cạnh | J20: 3 | L20: =+B11*1000-C28*2 -> 5100 | N20: =C22 -> 8 | O20: =+K20+L20+M20 -> 5100 | P20: =S84 -> 27 | Q20: =((P20*O20)/1000) -> 137.7 | R20: =+VLOOKUP(N20,CT,3,0)*Q20 -> 54.3915 | S20: Thanh ngang trong đài (lớp dưới) | AF20: =AG29+2*(AE21*AE17) -> 6.8
K21: =ROUND(P85,-1) -> 700 | L21: =ROUND(O85,-1) -> 3730 | AE21: 2
A22: đai cột | B22: f | C22: 8 | D22: a | E22: 200 | F22: chú ý cách bố trí bên dưới | J22: 4 | K22: =K18 -> 100 | M22: =K22 -> 100 | N22: =N20 -> 8 | O22: =L21+2*(K22+K21) -> 5330 | P22: =P20 -> 27 | Q22: =((P22*O22)/1000) -> 143.91 | R22: =+VLOOKUP(N22,CT,3,0)*Q22 -> 56.84445 | S22: Thanh ngang trong đài (lớp trên) | Z22: 87 | AA22: 1.7
A23: Bê tông lót | B23: 100 | C23: mm | L23: =AC69&"*" -> 270* | Z23: 94 | AA23: 2
A24: GHI CHÚ: | J24: 5 | K24: 100 | M24: =K24 -> 100 | N24: =N18 -> 12 | O24: =2*K24+AC69 -> 470 | P24: =AD68 -> 31 | Q24: =O24*AD68*E25/1000 -> 14.57 | R24: =+VLOOKUP(N24,CT,3,0)*Q24 -> 12.93816 | S24: Thép chống | Z24: 95 | AA24: 2
A25: * Số bản móng trong 1 móng: | E25: 1 | AE25: =B12+0.1-AE21 -> 0.6
A26: * Độ dốc mái đào hố móng:i=1: | E26: 0.5 | J26: 6 | K26: 300 | L26: =(B13+B12)*1000-C28-F28 -> 3400 | N26: =E20 -> 20 | O26: =L26+K26 -> 3700 | P26: =C20&"x4" -> 8x4 | Q26: =O26*C20*4/1000 -> 118.4 | R26: =+VLOOKUP(N26,CT,3,0)*Q26 -> 292.448 | S26: Thép cột
A27: * Lớp bê tông bảo vệ cốt thép: | L27: 60
A28: - Đáy móng: | C28: 50 | D28: - VT khác: | F28: 50 | J28: 7 | L28: =(D15*1000-2*F28) -> 500 | N28: =C22 -> 8 | O28: =L28*4+2*L27 -> 2120 | P28: =T28&"x4" -> 16x4 | Q28: =O28*T28*4/1000 -> 135.68 | R28: =+VLOOKUP(N28,CT,3,0)*Q28 -> 53.5936 | S28: Đai cột | T28: =(CEILING(((B13+B12-B16)*1000-F28)/$E$18,1)) -> 16 | AH28: =B10+0.6 -> 5.2
A29: * Bố trí đai dầm: | C29: c = | D29: 0 | E29: d = | F29: 0 | AG29: =AH28+0.6 -> 5.8
A30: * Bố trí đai cột: | C30: e = | D30: 1 | E30: f = | F30: 1 | J30: 8 | K30: =AL62 -> 270 | L30: 60 | N30: =C22 -> 8 | O30: =(K30+L31)*4+2*L30 -> 1840 | P30: =P28 -> 16x4 | Q30: =O30*T30*4/1000 -> 117.76 | R30: =+VLOOKUP(N30,CT,3,0)*Q30 -> 46.5152 | S30: Đai cột | T30: =T28 -> 16
L31: =AM62 -> 160
J32: 9 | K32: =M32 -> 60 | L32: =L28 -> 500 | M32: 60 | N32: =C22 -> 8 | O32: =L32+2*M32 -> 620 | P32: =T32&"x4" -> 32x4 | Q32: =O32*T32*4/1000 -> 79.36 | R32: =+VLOOKUP(N32,CT,3,0)*Q32 -> 31.3472 | S32: Đai cột | T32: =T30*D30*2 -> 32
J34: 10 | L34: =B15*1000-2*F28 -> 500 | N34: =N32 -> 8 | O34: =L34 -> 500 | P34: =(ROUND(O34/100,0))*2*2*4 -> 80 | Q34: =O34*P34/1000 -> 40 | R34: =+VLOOKUP(N34,CT,3,0)*Q34 -> 15.8 | S34: Gia cường cổ móng 2 lớp d @100
J35: OUTPUT 3: | K35: BẢNG PHÂN LOẠI THÉP | P35: Dự phòng khối lượng thép: | R35: 5 | S35: %
J36: f (mm) | K36: 8 | L36: 10 | M36: =N16 -> 12 | N36: 20 | O36: 25 | P36: KL COPHA: | Q36: * Bản móng: | R36: =(B10+B11)*2*B17 -> 3.92 | S36: m2
J37: Chiều dài (m) | K37: =+(1+0.01*R35)*SUMIF($N$16:$N$34,K36,$Q$16:$Q$34) -> 687.1305 | L37: =+(1+0.01*R35)*SUMIF($N$16:$N$34,L36,$Q$16:$Q$34) -> 0 | M37: =+(1+0.01*R35)*SUMIF($N$16:$N$34,M36,$Q$16:$Q$34) -> 238.9275 | N37: =+(1+0.01*R35)*SUMIF($N$16:$N$34,N36,$Q$16:$Q$34) -> 124.32 | O37: =+(1+0.01*R35)*SUMIF($N$16:$N$34,O36,$Q$16:$Q$34) -> 0 | Q37: * Dầm móng: | S37: m2
J38: TL (kg) | K38: =+(1+0.01*R35)*SUMIF($N$16:$N$34,K36,$R$16:$R$34) -> 271.41655 | L38: =+(1+0.01*R35)*SUMIF($N$16:$N$34,L36,$R$16:$R$34) -> 0 | M38: =+(1+0.01*R35)*SUMIF($N$16:$N$34,M36,$R$16:$R$34) -> 212.16762 | N38: =+(1+0.01*R35)*SUMIF($N$16:$N$34,N36,$R$16:$R$34) -> 307.0704 | O38: =+(1+0.01*R35)*SUMIF($N$16:$N$34,O36,$R$16:$R$34) -> 0 | Q38: * Cổ móng: | R38: =B15*4*(B12+B13-B16)*4 -> 29.76 | S38: m2
A44: Thống kê thanh số 2 (cho 1 trụ móng) | M44: Thống kê thanh số 4 (cho 1 trụ móng) | AA44: Thống kê thanh số 5 (cho 1 trụ móng) | AJ44: Thống kê thanh số 6 (cho 1 trụ móng)
AB46: Bố trí thép : | AC46: =C19 -> 12 | AD46: @ | AE46: =E19 -> 600
AB47: Trên đoạn X có : | AC47: =FLOOR((B59*1000)/$AE$46,1) -> 0 | AD47: hàng
...

Sheet Bảng tra
A1: Bê tông | H1: Cốt thép
A2: STT | B2: Mác | C2: Tên | D2: Rb(Mpa) | E2: Rbt(Mpa) | F2: E(Mpa) | H2: STT | I2: Tên | J2: Rs (Mpa) | K2: Rsc (Mpa) | L2: Rsw (Mpa) | M2: E (Mpa)
A3: 1 | B3: M200 | C3: B15 | D3: 8.5 | E3: 0.75 | F3: 24000 | H3: 1 | I3: CB240-T | J3: 210 | K3: 210 | L3: 170 | M3: 200000
A4: 2 | B4: M250 | C4: B20 | D4: 11.5 | E4: 0.9 | F4: 27500 | H4: 2 | I4: CB300-V | J4: 260 | K4: 260 | L4: 210 | M4: 200000
A5: 3 | B5: M300 | C5: B22.5 | D5: 13 | E5: 1 | F5: 28750 | H5: 3 | I5: CB400-V | J5: 350 | K5: 350 | L5: 280 | M5: 200000
A6: 4 | B6: M350 | C6: B25 | D6: 14.5 | E6: 1.05 | F6: 30000 | H6: 4 | I6: CB500-V | J6: 435 | K6: 400 | L6: 300 | M6: 200000
A7: 5 | B7: M400 | C7: B30 | D7: 17 | E7: 1.15 | F7: 32500
A8: 6 | B8: M450 | C8: B35 | D8: 19.5 | E8: 1.3 | F8: 34500
A9: 7 | B9: M500 | C9: B40 | D9: 22 | E9: 1.4 | F9: 36000
A10: 8 | B10: M600 | C10: B45 | D10: 25 | E10: 1.5 | F10: 37000 | H10: M250 | I10: =VLOOKUP(H10,B3:C13,2,0) -> B20
A11: 9 | B11: M700 | C11: B50 | D11: 27.5 | E11: 1.6 | F11: 38000
A12: 10 | B12: M700 | C12: B55 | D12: 30 | E12: 1.7 | F12: 39000
A13: 11 | B13: M800 | C13: B60 | D13: 33 | E13: 1.8 | F13: 39500
B14: Chú ý: 1MPa = 100T/m2
A17: f (mm) | B17: dtích (cm2) | C17: TL/m (kg)
A18: 6 | B18: 0.283 | C18: 0.222
A19: 8 | B19: 0.503 | C19: 0.395
A20: 10 | B20: 0.785 | C20: 0.717
A21: 12 | B21: 1.13 | C21: 0.888
A22: 14 | B22: 1.54 | C22: 1.21
A23: 16 | B23: 2.01 | C23: 1.58
A24: 18 | B24: 2.55 | C24: 2
A25: 20 | B25: 3.14 | C25: 2.47
A26: 22 | B26: 3.8 | C26: 2.98
A27: 25 | B27: 4.91 | C27: 3.85
A28: 28 | B28: 6.16 | C28: 4.83
A29: 30 | B29: 7.069 | C29: 5.549
... A33: 40 | B33: 12.57 | C33: 9.86
